<?xml version = "1.0"?>

<robot name="four_wheeled_differential_drive_robot">
    
    <!--BASE LINK-->
    <link name="base_link">
        <visual>
            <geometry>
                <box size="0.4 0.2 0.1"/>
            </geometry>
            <origin xyz="0 0 0.05" rpy="0 0 0"/>
            <material name="red">
                <color rgba="1 0.0 0.0 1.0"/>
            </material>
        </visual>
    </link>



    <!--Front Wheels-->
    <link name="front_right_wheel">
        <visual>
            <geometry>
                <cylinder radius="0.05" length="0.02"/>
            </geometry>
            <origin xyz="0 0 0" rpy="1.5708 0 0"/>
            <material name="black">
                <color rgba="0.0 0.0 0.0 1.0"/>
            </material>
        </visual>
    </link>

    <joint name="front_right_wheel_joint" type="continuous">
        <parent link="base_link"/>
        <child link="front_right_wheel"/>
        <origin xyz="0.15 -0.11 0" rpy="0 0 0"/>
        <axis xyz="0 1 0"/>
    </joint>

    <link name="front_left_wheel">
        <visual>
            <geometry>
                <cylinder radius="0.05" length="0.02"/>
            </geometry>
            <origin xyz="0 0 0" rpy="1.5708 0 0"/>
            <material name="black">
                <color rgba="0.0 0.0 0.0 1.0"/>
            </material>
        </visual>
    </link>

    <joint name="front_left_wheel_joint" type="continuous">
        <parent link="base_link"/>
        <child link="front_left_wheel"/>
        <origin xyz="0.15 0.11 0" rpy="0 0 0"/>
        <axis xyz="0 1 0"/>
    </joint>

    <!--Rear Wheels-->
    <link name="rear_right_wheel">
        <visual>
            <geometry>
                <cylinder radius="0.05" length="0.02"/>
            </geometry>
            <origin xyz="0 0 0" rpy="1.5708 0 0"/>
            <material name="black">
                <color rgba="0.0 0.0 0.0 1.0"/>
            </material>
        </visual>
    </link>
    <joint name="rear_right_wheel_joint" type="continuous">
        <parent link="base_link"/>
        <child link="rear_right_wheel"/>
        <origin xyz="-0.15 -0.11 0" rpy="0 0 0"/>
        <axis xyz="0 1 0"/>
    </joint>

    <link name="rear_left_wheel">
        <visual>
            <geometry>
                <cylinder radius="0.05" length="0.02"/>
            </geometry>
            <origin xyz="0 0 0" rpy="1.5708 0 0"/>
            <material name="black">
                <color rgba="0.0 0.0 0.0 1.0"/>
            </material>
        </visual>
    </link>

    <joint name="rear_left_wheel_joint" type="continuous">
        <parent link="base_link"/>
        <child link="rear_left_wheel"/>
        <origin xyz="-0.15 0.11 0" rpy="0 0 0"/>
        <axis xyz="0 1 0"/>
    </joint>


</robot>
